<?xml version="1.0"?>
<robot name="stepbot" xmlns:xacro="http://ros.org/wiki/xacro">

 <!-- Define robot constants -->
 
 <link name="base_footprint" />

 <joint name="base_joint" type="fixed">
  <parent link="base_link"/>
  <child link="base_footprint"/>
  <origin xyz="0 0 -0.0255" rpy="0 0 0"/>
 </joint>

 <!-- Robot Base -->
 <link name="base_link">
  <visual>
   <origin xyz="0 0 0.0255" rpy="0 0 0"/>
   <geometry>
    <box size="0.130 0.120 0.10"/>
   </geometry>
   <material name="blue">
    <color rgba="0.0 0.0 1.0 1.0"/>
   </material>
  </visual>
  <collision>
   <geometry>
    <box size="0.130 0.120 0.10"/>
   </geometry>
  </collision>
 </link>

<!-- Wheel Definition -->
 <joint name="wheel_left_joint" type="continuous">
  <origin xyz="0 0.05 0" rpy="${radians(-90)} 0 0"/>
  <parent link="base_link"/>
  <child link="wheel_left"/>
  <axis xyz="0 0 1"/>
 </joint>

 <link name="wheel_left">
  <inertial>
   <origin xyz="0 0 0" rpy="0 0 0"/>
   <mass value="1.0"/>
   <inertia ixx="0.001" ixy="0.0" ixz="0.0" iyy="0.001" iyz="0.0" izz="0.001"/>
  </inertial>
  <visual>
   <geometry>
    <cylinder radius="0.0255" length="0.005"/>
   </geometry>
  </visual>
  <collision>
   <geometry>
    <cylinder radius="0.0255" length="0.005"/>
   </geometry>
  </collision>
 </link>

 <joint name="wheel_right_joint" type="continuous">
  <origin xyz="0 -0.05 0" rpy="${radians(-90)} 0 0"/>
  <parent link="base_link"/>
  <child link="wheel_right"/>
  <axis xyz="0 0 1"/>
 </joint>

 <link name="wheel_right">
  <inertial>
   <origin xyz="0 0 0" rpy="0 0 0"/>
   <mass value="1.0"/>
   <inertia ixx="0.001" ixy="0.0" ixz="0.0" iyy="0.001" iyz="0.0" izz="0.001"/>
  </inertial>
  <visual>
   <geometry>
    <cylinder radius="0.0255" length="0.005"/>
   </geometry>
  </visual>
  <collision>
   <geometry>
    <cylinder radius="0.0255" length="0.005"/>
   </geometry>
  </collision>
 </link>

<!-- LiDAR Definition -->
 <joint name="lidar_joint" type="fixed">
  <parent link="base_link"/>
  <child link="base_scan"/>
  <origin xyz="0.03 0 0.114" rpy="0 0 0"/>
 </joint>
 <link name="base_scan">
  <inertial>
   <mass value="1.0"/>
   <inertia ixx="0.001" ixy="0.0" ixz="0.0" iyy="0.001" iyz="0.0" izz="0.001"/>
  </inertial>
  <visual>
   <geometry>
    <cylinder length="0.0126" radius="0.017645"/>
   </geometry>
  </visual>
  <collision>
   <geometry>
    <cylinder length="0.0126" radius="0.017645"/>
   </geometry>
  </collision>
 </link>

<!-- include OAK-D S2 -->
 <xacro:include filename="$(find depthai_descriptions)/urdf/include/depthai_macro.urdf.xacro"/>

 <joint name="oak_joint" type="fixed">
  <parent link="base_link"/>
  <child link="oak-d-base-frame"/>
  <origin xyz="0.08 0 0.095" rpy="0 0 0"/>
 </joint>

 <link name="oak-d-base-frame" />

 <xacro:depthai_camera camera_name= "oak" camera_model = "OAK-D-S2" 
                       base_frame = "oak-d_frame" parent="oak-d-base-frame"
                       cam_pos_x = "0" cam_pos_y = "0" cam_pos_z = "0"
                       cam_roll = "0" cam_pitch = "0" cam_yaw = "0"/>

</robot>

